[2025-10-17T00:11:42.106+0000] {local_task_job_runner.py:120} INFO - ::group::Pre task execution logs
[2025-10-17T00:11:42.119+0000] {taskinstance.py:2076} INFO - Dependencies all met for dep_context=non-requeueable deps ti=<TaskInstance: silver_transform.run_sql manual__2025-10-17T00:11:40.543567+00:00 [queued]>
[2025-10-17T00:11:42.122+0000] {taskinstance.py:2076} INFO - Dependencies all met for dep_context=requeueable deps ti=<TaskInstance: silver_transform.run_sql manual__2025-10-17T00:11:40.543567+00:00 [queued]>
[2025-10-17T00:11:42.122+0000] {taskinstance.py:2306} INFO - Starting attempt 1 of 1
[2025-10-17T00:11:42.126+0000] {taskinstance.py:2330} INFO - Executing <Task(PythonOperator): run_sql> on 2025-10-17 00:11:40.543567+00:00
[2025-10-17T00:11:42.131+0000] {logging_mixin.py:188} WARNING - /home/***/.local/lib/python3.12/site-packages/***/task/task_runner/standard_task_runner.py:61 DeprecationWarning: This process (pid=208) is multi-threaded, use of fork() may lead to deadlocks in the child.
[2025-10-17T00:11:42.131+0000] {standard_task_runner.py:63} INFO - Started process 211 to run task
[2025-10-17T00:11:42.131+0000] {standard_task_runner.py:90} INFO - Running: ['***', 'tasks', 'run', 'silver_transform', 'run_sql', 'manual__2025-10-17T00:11:40.543567+00:00', '--job-id', '88', '--raw', '--subdir', 'DAGS_FOLDER/silver_transform_dag.py', '--cfg-path', '/tmp/tmpellh4x0z']
[2025-10-17T00:11:42.132+0000] {standard_task_runner.py:91} INFO - Job 88: Subtask run_sql
[2025-10-17T00:11:42.141+0000] {logging_mixin.py:188} WARNING - /home/***/.local/lib/python3.12/site-packages/***/settings.py:195 DeprecationWarning: The sql_alchemy_conn option in [core] has been moved to the sql_alchemy_conn option in [database] - the old setting has been used, but please update your config.
[2025-10-17T00:11:42.155+0000] {task_command.py:426} INFO - Running <TaskInstance: silver_transform.run_sql manual__2025-10-17T00:11:40.543567+00:00 [running]> on host 728de341d734
[2025-10-17T00:11:42.189+0000] {taskinstance.py:2648} INFO - Exporting env vars: AIRFLOW_CTX_DAG_OWNER='***' AIRFLOW_CTX_DAG_ID='silver_transform' AIRFLOW_CTX_TASK_ID='run_sql' AIRFLOW_CTX_EXECUTION_DATE='2025-10-17T00:11:40.543567+00:00' AIRFLOW_CTX_TRY_NUMBER='1' AIRFLOW_CTX_DAG_RUN_ID='manual__2025-10-17T00:11:40.543567+00:00'
[2025-10-17T00:11:42.189+0000] {taskinstance.py:430} INFO - ::endgroup::
[2025-10-17T00:11:42.198+0000] {connection.py:399} INFO - Snowflake Connector for Python Version: 3.10.1, Python Version: 3.12.4, Platform: Linux-6.10.14-linuxkit-aarch64-with-glibc2.36
[2025-10-17T00:11:42.198+0000] {connection.py:1239} INFO - This connection is in OCSP Fail Open Mode. TLS Certificates would be checked for validity and revocation status. Any other Certificate Revocation related exceptions or OCSP Responder failures would be disregarded in favor of connectivity.
[2025-10-17T00:11:42.763+0000] {logging_mixin.py:188} INFO - 
[SQL] Executing statement:
USE WAREHOUSE COMPUTE_WH
[2025-10-17T00:11:42.898+0000] {cursor.py:1149} INFO - Number of results in first chunk: 1
[2025-10-17T00:11:42.899+0000] {logging_mixin.py:188} INFO - 
[SQL] Executing statement:
USE DATABASE COVID_DB
[2025-10-17T00:11:43.013+0000] {cursor.py:1149} INFO - Number of results in first chunk: 1
[2025-10-17T00:11:43.014+0000] {logging_mixin.py:188} INFO - 
[SQL] Executing statement:
CREATE SCHEMA IF NOT EXISTS SILVER
[2025-10-17T00:11:43.128+0000] {cursor.py:1149} INFO - Number of results in first chunk: 1
[2025-10-17T00:11:43.129+0000] {logging_mixin.py:188} INFO - 
[SQL] Executing statement:
CREATE OR REPLACE TABLE SILVER.CASES_CLEAN AS
SELECT *
FROM (
  SELECT
    UPPER(ISO_CODE) AS iso_code,
    CASE
      WHEN TRY_TO_DATE(TO_VARCHAR(date)) IS NOT NULL THEN TRY_TO_DATE(TO_VARCHAR(date))
      WHEN TRY_TO_DATE(TO_VARCHAR(date), 'YYYY-MM-DD') IS NOT NULL THEN TO_DATE(TO_VARCHAR(date), 'YYYY-MM-DD')
      WHEN TRY_TO_DATE(TO_VARCHAR(date), 'YYYY/MM/DD') IS NOT NULL THEN TO_DATE(TO_VARC...
[2025-10-17T00:11:43.282+0000] {connection.py:762} INFO - closed
[2025-10-17T00:11:43.364+0000] {connection.py:768} INFO - No async queries seem to be running, deleting session
[2025-10-17T00:11:43.444+0000] {taskinstance.py:441} INFO - ::group::Post task execution logs
[2025-10-17T00:11:43.445+0000] {taskinstance.py:2905} ERROR - Task failed with exception
Traceback (most recent call last):
  File "/home/airflow/.local/lib/python3.12/site-packages/airflow/models/taskinstance.py", line 465, in _execute_task
    result = _execute_callable(context=context, **execute_callable_kwargs)
             ^^^^^^^^^^^^^^^^^^^^^^^^^^^^^^^^^^^^^^^^^^^^^^^^^^^^^^^^^^^^^
  File "/home/airflow/.local/lib/python3.12/site-packages/airflow/models/taskinstance.py", line 432, in _execute_callable
    return execute_callable(context=context, **execute_callable_kwargs)
           ^^^^^^^^^^^^^^^^^^^^^^^^^^^^^^^^^^^^^^^^^^^^^^^^^^^^^^^^^^^^
  File "/home/airflow/.local/lib/python3.12/site-packages/airflow/models/baseoperator.py", line 401, in wrapper
    return func(self, *args, **kwargs)
           ^^^^^^^^^^^^^^^^^^^^^^^^^^^
  File "/home/airflow/.local/lib/python3.12/site-packages/airflow/operators/python.py", line 235, in execute
    return_value = self.execute_callable()
                   ^^^^^^^^^^^^^^^^^^^^^^^
  File "/home/airflow/.local/lib/python3.12/site-packages/airflow/operators/python.py", line 252, in execute_callable
    return self.python_callable(*self.op_args, **self.op_kwargs)
           ^^^^^^^^^^^^^^^^^^^^^^^^^^^^^^^^^^^^^^^^^^^^^^^^^^^^^
  File "/opt/airflow/dags/silver_transform_dag.py", line 275, in run_sql
    cs.execute(stmt)
  File "/home/airflow/.local/lib/python3.12/site-packages/snowflake/connector/cursor.py", line 1080, in execute
    Error.errorhandler_wrapper(self.connection, self, error_class, errvalue)
  File "/home/airflow/.local/lib/python3.12/site-packages/snowflake/connector/errors.py", line 290, in errorhandler_wrapper
    handed_over = Error.hand_to_other_handler(
                  ^^^^^^^^^^^^^^^^^^^^^^^^^^^^
  File "/home/airflow/.local/lib/python3.12/site-packages/snowflake/connector/errors.py", line 345, in hand_to_other_handler
    cursor.errorhandler(connection, cursor, error_class, error_value)
  File "/home/airflow/.local/lib/python3.12/site-packages/snowflake/connector/errors.py", line 221, in default_errorhandler
    raise error_class(
snowflake.connector.errors.ProgrammingError: 001007 (22023): 01bfc24b-0001-095d-0000-c8f100030076: SQL compilation error:
invalid type [TRY_TO_NUMBER(CASES_DATASET.DATE)] for parameter 'TO_NUMBER'
[2025-10-17T00:11:43.453+0000] {taskinstance.py:1206} INFO - Marking task as FAILED. dag_id=silver_transform, task_id=run_sql, run_id=manual__2025-10-17T00:11:40.543567+00:00, execution_date=20251017T001140, start_date=20251017T001142, end_date=20251017T001143
[2025-10-17T00:11:43.460+0000] {standard_task_runner.py:110} ERROR - Failed to execute job 88 for task run_sql (001007 (22023): 01bfc24b-0001-095d-0000-c8f100030076: SQL compilation error:
invalid type [TRY_TO_NUMBER(CASES_DATASET.DATE)] for parameter 'TO_NUMBER'; 211)
[2025-10-17T00:11:43.473+0000] {local_task_job_runner.py:240} INFO - Task exited with return code 1
[2025-10-17T00:11:43.481+0000] {taskinstance.py:3503} INFO - 0 downstream tasks scheduled from follow-on schedule check
[2025-10-17T00:11:43.482+0000] {local_task_job_runner.py:222} INFO - ::endgroup::
