[2025-10-19T06:12:30.378+0000] {local_task_job_runner.py:120} INFO - ::group::Pre task execution logs
[2025-10-19T06:12:30.400+0000] {taskinstance.py:2076} INFO - Dependencies all met for dep_context=non-requeueable deps ti=<TaskInstance: silver_to_gold.build_country_latest_snapshot manual__2025-10-19T06:12:20.717544+00:00 [queued]>
[2025-10-19T06:12:30.405+0000] {taskinstance.py:2076} INFO - Dependencies all met for dep_context=requeueable deps ti=<TaskInstance: silver_to_gold.build_country_latest_snapshot manual__2025-10-19T06:12:20.717544+00:00 [queued]>
[2025-10-19T06:12:30.405+0000] {taskinstance.py:2306} INFO - Starting attempt 1 of 1
[2025-10-19T06:12:30.413+0000] {taskinstance.py:2330} INFO - Executing <Task(PythonOperator): build_country_latest_snapshot> on 2025-10-19 06:12:20.717544+00:00
[2025-10-19T06:12:30.419+0000] {logging_mixin.py:188} WARNING - /home/***/.local/lib/python3.12/site-packages/***/task/task_runner/standard_task_runner.py:61 DeprecationWarning: This process (pid=274) is multi-threaded, use of fork() may lead to deadlocks in the child.
[2025-10-19T06:12:30.419+0000] {standard_task_runner.py:90} INFO - Running: ['***', 'tasks', 'run', 'silver_to_gold', 'build_country_latest_snapshot', 'manual__2025-10-19T06:12:20.717544+00:00', '--job-id', '169', '--raw', '--subdir', 'DAGS_FOLDER/gold_build_dag.py', '--cfg-path', '/tmp/tmpg9b7bh5l']
[2025-10-19T06:12:30.420+0000] {standard_task_runner.py:63} INFO - Started process 284 to run task
[2025-10-19T06:12:30.421+0000] {standard_task_runner.py:91} INFO - Job 169: Subtask build_country_latest_snapshot
[2025-10-19T06:12:30.435+0000] {logging_mixin.py:188} WARNING - /home/***/.local/lib/python3.12/site-packages/***/settings.py:195 DeprecationWarning: The sql_alchemy_conn option in [core] has been moved to the sql_alchemy_conn option in [database] - the old setting has been used, but please update your config.
[2025-10-19T06:12:30.464+0000] {task_command.py:426} INFO - Running <TaskInstance: silver_to_gold.build_country_latest_snapshot manual__2025-10-19T06:12:20.717544+00:00 [running]> on host 728de341d734
[2025-10-19T06:12:30.545+0000] {taskinstance.py:2648} INFO - Exporting env vars: AIRFLOW_CTX_DAG_OWNER='data-eng' AIRFLOW_CTX_DAG_ID='silver_to_gold' AIRFLOW_CTX_TASK_ID='build_country_latest_snapshot' AIRFLOW_CTX_EXECUTION_DATE='2025-10-19T06:12:20.717544+00:00' AIRFLOW_CTX_TRY_NUMBER='1' AIRFLOW_CTX_DAG_RUN_ID='manual__2025-10-19T06:12:20.717544+00:00'
[2025-10-19T06:12:30.547+0000] {taskinstance.py:430} INFO - ::endgroup::
[2025-10-19T06:12:30.557+0000] {connection.py:399} INFO - Snowflake Connector for Python Version: 3.10.1, Python Version: 3.12.4, Platform: Linux-6.10.14-linuxkit-aarch64-with-glibc2.36
[2025-10-19T06:12:30.557+0000] {connection.py:1239} INFO - This connection is in OCSP Fail Open Mode. TLS Certificates would be checked for validity and revocation status. Any other Certificate Revocation related exceptions or OCSP Responder failures would be disregarded in favor of connectivity.
[2025-10-19T06:12:31.243+0000] {cursor.py:1149} INFO - Number of results in first chunk: 1
[2025-10-19T06:12:31.378+0000] {cursor.py:1149} INFO - Number of results in first chunk: 1
[2025-10-19T06:12:31.578+0000] {connection.py:762} INFO - closed
[2025-10-19T06:12:31.655+0000] {connection.py:768} INFO - No async queries seem to be running, deleting session
[2025-10-19T06:12:31.734+0000] {taskinstance.py:441} INFO - ::group::Post task execution logs
[2025-10-19T06:12:31.735+0000] {taskinstance.py:2905} ERROR - Task failed with exception
Traceback (most recent call last):
  File "/home/airflow/.local/lib/python3.12/site-packages/airflow/models/taskinstance.py", line 465, in _execute_task
    result = _execute_callable(context=context, **execute_callable_kwargs)
             ^^^^^^^^^^^^^^^^^^^^^^^^^^^^^^^^^^^^^^^^^^^^^^^^^^^^^^^^^^^^^
  File "/home/airflow/.local/lib/python3.12/site-packages/airflow/models/taskinstance.py", line 432, in _execute_callable
    return execute_callable(context=context, **execute_callable_kwargs)
           ^^^^^^^^^^^^^^^^^^^^^^^^^^^^^^^^^^^^^^^^^^^^^^^^^^^^^^^^^^^^
  File "/home/airflow/.local/lib/python3.12/site-packages/airflow/models/baseoperator.py", line 401, in wrapper
    return func(self, *args, **kwargs)
           ^^^^^^^^^^^^^^^^^^^^^^^^^^^
  File "/home/airflow/.local/lib/python3.12/site-packages/airflow/operators/python.py", line 235, in execute
    return_value = self.execute_callable()
                   ^^^^^^^^^^^^^^^^^^^^^^^
  File "/home/airflow/.local/lib/python3.12/site-packages/airflow/operators/python.py", line 252, in execute_callable
    return self.python_callable(*self.op_args, **self.op_kwargs)
           ^^^^^^^^^^^^^^^^^^^^^^^^^^^^^^^^^^^^^^^^^^^^^^^^^^^^^
  File "/opt/airflow/dags/gold_build_dag.py", line 37, in run_sql
    cs.execute(stmt)
  File "/home/airflow/.local/lib/python3.12/site-packages/snowflake/connector/cursor.py", line 1080, in execute
    Error.errorhandler_wrapper(self.connection, self, error_class, errvalue)
  File "/home/airflow/.local/lib/python3.12/site-packages/snowflake/connector/errors.py", line 290, in errorhandler_wrapper
    handed_over = Error.hand_to_other_handler(
                  ^^^^^^^^^^^^^^^^^^^^^^^^^^^^
  File "/home/airflow/.local/lib/python3.12/site-packages/snowflake/connector/errors.py", line 345, in hand_to_other_handler
    cursor.errorhandler(connection, cursor, error_class, error_value)
  File "/home/airflow/.local/lib/python3.12/site-packages/snowflake/connector/errors.py", line 221, in default_errorhandler
    raise error_class(
snowflake.connector.errors.ProgrammingError: 002025 (42S21): 01bfcef4-0001-09d9-0000-c8f10004f2a2: SQL compilation error:
duplicate column name 'VACCINATED_COVERAGE_PCT'
[2025-10-19T06:12:31.746+0000] {taskinstance.py:1206} INFO - Marking task as FAILED. dag_id=silver_to_gold, task_id=build_country_latest_snapshot, run_id=manual__2025-10-19T06:12:20.717544+00:00, execution_date=20251019T061220, start_date=20251019T061230, end_date=20251019T061231
[2025-10-19T06:12:31.754+0000] {standard_task_runner.py:110} ERROR - Failed to execute job 169 for task build_country_latest_snapshot (002025 (42S21): 01bfcef4-0001-09d9-0000-c8f10004f2a2: SQL compilation error:
duplicate column name 'VACCINATED_COVERAGE_PCT'; 284)
[2025-10-19T06:12:31.787+0000] {local_task_job_runner.py:240} INFO - Task exited with return code 1
[2025-10-19T06:12:31.794+0000] {local_task_job_runner.py:222} INFO - ::endgroup::
